DRIVER - Debug mode enabled
PUB<A,B,C> - Successfully initialized publisher object (PUB139780025678144)
PUB<A,B,C> - Try to connect with ZooKeeper server: hosts = 10.0.0.1:2181
PUB<A,B,C> - ZooKeeper Current Status = LOST
PUB<A,B,C> - Current state is now = CONNECTED
PUB<A,B,C> - out of all zones (['zone_1', 'zone_2']), choosing zone_2
PUB<A,B,C>:offer=1:zone_2 - Checking if Znode /primaries/zone_2 exists
PUB<A,B,C>:offer=1:zone_2 - Details of znode /primaries/zone_2: value = b"b'10.0.0.3,5555,5556'", stat = ZnodeStat(czxid=5817, mzxid=12144, ctime=1627231871278, mtime=1627231959574, version=1, cversion=0, aversion=0, ephemeralOwner=0, dataLength=21, numChildren=0, pzxid=5817)
PUB<A,B,C>:offer=1:zone_2 - Getting broker information from znode_value
PUB<A,B,C>:offer=1:zone_2 - Broker address: b'10.0.0.3
PUB<A,B,C>:offer=1:zone_2 - Broker Pub Reg Port: 5555
PUB<A,B,C>:offer=1:zone_2 - No ZNODE Event - First Watch Call! Initializing publisher...
PUB<A,B,C>:offer=1:zone_2 - Checking if Znode /primaries/zone_2 exists
PUB<A,B,C>:offer=1:zone_2 - Details of znode /primaries/zone_2: value = b"b'10.0.0.3,5555,5556'", stat = ZnodeStat(czxid=5817, mzxid=12144, ctime=1627231871278, mtime=1627231959574, version=1, cversion=0, aversion=0, ephemeralOwner=0, dataLength=21, numChildren=0, pzxid=5817)
PUB<A,B,C>:offer=1:zone_2 - Getting broker information from znode_value
PUB<A,B,C>:offer=1:zone_2 - Broker address: b'10.0.0.3
PUB<A,B,C>:offer=1:zone_2 - Broker Pub Reg Port: 5555
PUB<A,B,C>:offer=1:zone_2 - Configure Start
PUB<A,B,C>:offer=1:zone_2 - Initializing
PUB<A,B,C>:offer=1:zone_2 - Setting the context object
PUB<A,B,C>:offer=1:zone_2 - Connecting to register with broker
Invalid argument
Traceback (most recent call last):
  File "/usr/lib/python3.8/site-packages/kazoo/recipe/watchers.py", line 162, in _log_func_exception
    result = self._func(data, stat, event)
  File "/mnt/dev/assign3/src/lib/publisher.py", line 130, in dump_data_change
    self.configure()
  File "/mnt/dev/assign3/src/lib/publisher.py", line 157, in configure
    self.broker_reg_socket.connect(f"tcp://{self.broker_address}:{self.pub_reg_port}")
  File "/usr/lib/python3.8/site-packages/zmq/sugar/socket.py", line 194, in connect
    super().connect(addr)
  File "zmq/backend/cython/socket.pyx", line 573, in zmq.backend.cython.socket.Socket.connect
  File "zmq/backend/cython/checkrc.pxd", line 28, in zmq.backend.cython.checkrc._check_rc
zmq.error.ZMQError: Invalid argument
Traceback (most recent call last):
  File "driver.py", line 308, in <module>
    publishers = create_publishers(
  File "driver.py", line 57, in create_publishers
    create_publisher_with_zookeeper(pubs[i])
  File "driver.py", line 18, in create_publisher_with_zookeeper
    publisher.watch_znode_data_change()
  File "/mnt/dev/assign3/src/lib/publisher.py", line 125, in watch_znode_data_change
    def dump_data_change (data, stat, event):
  File "/usr/lib/python3.8/site-packages/kazoo/recipe/watchers.py", line 152, in __call__
    self._get_data()
  File "/usr/lib/python3.8/site-packages/kazoo/recipe/watchers.py", line 37, in wrapper
    return func(*args, **kwargs)
  File "/usr/lib/python3.8/site-packages/kazoo/recipe/watchers.py", line 206, in _get_data
    self._log_func_exception(data, stat, event)
  File "/usr/lib/python3.8/site-packages/kazoo/recipe/watchers.py", line 162, in _log_func_exception
    result = self._func(data, stat, event)
  File "/mnt/dev/assign3/src/lib/publisher.py", line 130, in dump_data_change
    self.configure()
  File "/mnt/dev/assign3/src/lib/publisher.py", line 157, in configure
    self.broker_reg_socket.connect(f"tcp://{self.broker_address}:{self.pub_reg_port}")
  File "/usr/lib/python3.8/site-packages/zmq/sugar/socket.py", line 194, in connect
    super().connect(addr)
  File "zmq/backend/cython/socket.pyx", line 573, in zmq.backend.cython.socket.Socket.connect
  File "zmq/backend/cython/checkrc.pxd", line 28, in zmq.backend.cython.checkrc._check_rc
zmq.error.ZMQError: Invalid argument
